Encountered an exception while running action 'utter_translate_data'. Bot will continue, but the actions events are lost. Make sure to fix the exception in your custom code.
HTTPSConnectionPool(host='www.google.co.in', port=443): Max retries exceeded with url: /search?q=translate+dog+in+tamil&ie=UTF-8 (Caused by ProxyError('Cannot connect to proxy.', OSError('Tunnel connection failed: 407 Proxy Authentication Required',)))
Traceback (most recent call last):
  File "D:\Softwares\anaconda\lib\site-packages\urllib3\connectionpool.py", line 595, in urlopen
    self._prepare_proxy(conn)
  File "D:\Softwares\anaconda\lib\site-packages\urllib3\connectionpool.py", line 816, in _prepare_proxy
    conn.connect()
  File "D:\Softwares\anaconda\lib\site-packages\urllib3\connection.py", line 294, in connect
    self._tunnel()
  File "D:\Softwares\anaconda\lib\http\client.py", line 919, in _tunnel
    message.strip()))
OSError: Tunnel connection failed: 407 Proxy Authentication Required

During handling of the above exception, another exception occurred:

Traceback (most recent call last):
  File "D:\Softwares\anaconda\lib\site-packages\requests\adapters.py", line 440, in send
    timeout=timeout
  File "D:\Softwares\anaconda\lib\site-packages\urllib3\connectionpool.py", line 639, in urlopen
    _stacktrace=sys.exc_info()[2])
  File "D:\Softwares\anaconda\lib\site-packages\urllib3\util\retry.py", line 388, in increment
    raise MaxRetryError(_pool, url, error or ResponseError(cause))
urllib3.exceptions.MaxRetryError: HTTPSConnectionPool(host='www.google.co.in', port=443): Max retries exceeded with url: /search?q=translate+dog+in+tamil&ie=UTF-8 (Caused by ProxyError('Cannot connect to proxy.', OSError('Tunnel connection failed: 407 Proxy Authentication Required',)))

During handling of the above exception, another exception occurred:

Traceback (most recent call last):
  File "D:\Softwares\anaconda\lib\site-packages\rasa_core\processor.py", line 302, in _run_action
    events = action.run(dispatcher, tracker, self.domain)
  File "D:\Projects\ticket-bot\actions.py", line 92, in run
    message = translateGoogle(word, language)
  File "D:\Projects\ticket-bot\soup.py", line 42, in translateGoogle
    r = s.get('https://www.google.co.in/search?q=translate+{}+in+{}&ie=UTF-8'.format(word, language))
  File "D:\Softwares\anaconda\lib\site-packages\requests\sessions.py", line 521, in get
    return self.request('GET', url, **kwargs)
  File "D:\Softwares\anaconda\lib\site-packages\requests\sessions.py", line 508, in request
    resp = self.send(prep, **send_kwargs)
  File "D:\Softwares\anaconda\lib\site-packages\requests\sessions.py", line 618, in send
    r = adapter.send(request, **kwargs)
  File "D:\Softwares\anaconda\lib\site-packages\requests\adapters.py", line 502, in send
    raise ProxyError(e, request=request)
requests.exceptions.ProxyError: HTTPSConnectionPool(host='www.google.co.in', port=443): Max retries exceeded with url: /search?q=translate+dog+in+tamil&ie=UTF-8 (Caused by ProxyError('Cannot connect to proxy.', OSError('Tunnel connection failed: 407 Proxy Authentication Required',)))
Encountered an exception while running action 'utter_translate_data'. Bot will continue, but the actions events are lost. Make sure to fix the exception in your custom code.
HTTPSConnectionPool(host='www.google.co.in', port=443): Max retries exceeded with url: /search?q=translate+dog+in+tamil&ie=UTF-8 (Caused by ProxyError('Cannot connect to proxy.', OSError('Tunnel connection failed: 407 Proxy Authentication Required',)))
Traceback (most recent call last):
  File "D:\Softwares\anaconda\lib\site-packages\urllib3\connectionpool.py", line 595, in urlopen
    self._prepare_proxy(conn)
  File "D:\Softwares\anaconda\lib\site-packages\urllib3\connectionpool.py", line 816, in _prepare_proxy
    conn.connect()
  File "D:\Softwares\anaconda\lib\site-packages\urllib3\connection.py", line 294, in connect
    self._tunnel()
  File "D:\Softwares\anaconda\lib\http\client.py", line 919, in _tunnel
    message.strip()))
OSError: Tunnel connection failed: 407 Proxy Authentication Required

During handling of the above exception, another exception occurred:

Traceback (most recent call last):
  File "D:\Softwares\anaconda\lib\site-packages\requests\adapters.py", line 440, in send
    timeout=timeout
  File "D:\Softwares\anaconda\lib\site-packages\urllib3\connectionpool.py", line 639, in urlopen
    _stacktrace=sys.exc_info()[2])
  File "D:\Softwares\anaconda\lib\site-packages\urllib3\util\retry.py", line 388, in increment
    raise MaxRetryError(_pool, url, error or ResponseError(cause))
urllib3.exceptions.MaxRetryError: HTTPSConnectionPool(host='www.google.co.in', port=443): Max retries exceeded with url: /search?q=translate+dog+in+tamil&ie=UTF-8 (Caused by ProxyError('Cannot connect to proxy.', OSError('Tunnel connection failed: 407 Proxy Authentication Required',)))

During handling of the above exception, another exception occurred:

Traceback (most recent call last):
  File "D:\Softwares\anaconda\lib\site-packages\rasa_core\processor.py", line 302, in _run_action
    events = action.run(dispatcher, tracker, self.domain)
  File "D:\Projects\ticket-bot\actions.py", line 92, in run
    message = translateGoogle(word, language)
  File "D:\Projects\ticket-bot\soup.py", line 42, in translateGoogle
    r = s.get('https://www.google.co.in/search?q=translate+{}+in+{}&ie=UTF-8'.format(word, language))
  File "D:\Softwares\anaconda\lib\site-packages\requests\sessions.py", line 521, in get
    return self.request('GET', url, **kwargs)
  File "D:\Softwares\anaconda\lib\site-packages\requests\sessions.py", line 508, in request
    resp = self.send(prep, **send_kwargs)
  File "D:\Softwares\anaconda\lib\site-packages\requests\sessions.py", line 618, in send
    r = adapter.send(request, **kwargs)
  File "D:\Softwares\anaconda\lib\site-packages\requests\adapters.py", line 502, in send
    raise ProxyError(e, request=request)
requests.exceptions.ProxyError: HTTPSConnectionPool(host='www.google.co.in', port=443): Max retries exceeded with url: /search?q=translate+dog+in+tamil&ie=UTF-8 (Caused by ProxyError('Cannot connect to proxy.', OSError('Tunnel connection failed: 407 Proxy Authentication Required',)))
Rasa process starting
C:\TCL\Python\lib\site-packages\rasa_nlu\extractors\entity_synonyms.py:85: UserWarning: Failed to load synonyms file from './models/nlu/default/nlu_model\entity_synonyms.json'
  "".format(entity_synonyms_file))

Restoring parameters from ./models/nlu/default/nlu_model\intent_classifier_tensorflow_embedding.ckpt
C:\TCL\Python\lib\site-packages\pykwalify\core.py:99: UnsafeLoaderWarning: 
The default 'Loader' for 'load(stream)' without further arguments can be unsafe.
Use 'load(stream, Loader=ruamel.yaml.Loader)' explicitly if that is OK.
Alternatively include the following in your code:

  import warnings
  warnings.simplefilter('ignore', ruamel.yaml.error.UnsafeLoaderWarning)

In most other cases you should consider using 'safe_load(stream)'
  data = yaml.load(stream)

Rasa Core server is up and running on http://localhost:5005
Rasa process starting
C:\TCL\Python\lib\site-packages\rasa_nlu\extractors\entity_synonyms.py:85: UserWarning: Failed to load synonyms file from './models/nlu/default/nlu_model\entity_synonyms.json'
  "".format(entity_synonyms_file))

Restoring parameters from ./models/nlu/default/nlu_model\intent_classifier_tensorflow_embedding.ckpt
C:\TCL\Python\lib\site-packages\pykwalify\core.py:99: UnsafeLoaderWarning: 
The default 'Loader' for 'load(stream)' without further arguments can be unsafe.
Use 'load(stream, Loader=ruamel.yaml.Loader)' explicitly if that is OK.
Alternatively include the following in your code:

  import warnings
  warnings.simplefilter('ignore', ruamel.yaml.error.UnsafeLoaderWarning)

In most other cases you should consider using 'safe_load(stream)'
  data = yaml.load(stream)

Rasa Core server is up and running on http://localhost:5005
Failed to run custom action 'action_ticket_details'. Couldn't connect to the server at 'http://localhost:5055/webhook'. Is the server running? Error: HTTPConnectionPool(host='localhost', port=5055): Max retries exceeded with url: /webhook (Caused by NewConnectionError('<urllib3.connection.HTTPConnection object at 0x000001AC445DB4A8>: Failed to establish a new connection: [WinError 10061] No connection could be made because the target machine actively refused it',))
Encountered an exception while running action 'action_ticket_details'. Bot will continue, but the actions events are lost. Make sure to fix the exception in your custom code.
Failed to execute custom action.
Traceback (most recent call last):
  File "C:\TCL\Python\lib\site-packages\urllib3\connection.py", line 171, in _new_conn
    (self._dns_host, self.port), self.timeout, **extra_kw)
  File "C:\TCL\Python\lib\site-packages\urllib3\util\connection.py", line 79, in create_connection
    raise err
  File "C:\TCL\Python\lib\site-packages\urllib3\util\connection.py", line 69, in create_connection
    sock.connect(sa)
ConnectionRefusedError: [WinError 10061] No connection could be made because the target machine actively refused it

During handling of the above exception, another exception occurred:

Traceback (most recent call last):
  File "C:\TCL\Python\lib\site-packages\urllib3\connectionpool.py", line 600, in urlopen
    chunked=chunked)
  File "C:\TCL\Python\lib\site-packages\urllib3\connectionpool.py", line 354, in _make_request
    conn.request(method, url, **httplib_request_kw)
  File "C:\TCL\Python\lib\http\client.py", line 1239, in request
    self._send_request(method, url, body, headers, encode_chunked)
  File "C:\TCL\Python\lib\http\client.py", line 1285, in _send_request
    self.endheaders(body, encode_chunked=encode_chunked)
  File "C:\TCL\Python\lib\http\client.py", line 1234, in endheaders
    self._send_output(message_body, encode_chunked=encode_chunked)
  File "C:\TCL\Python\lib\http\client.py", line 1026, in _send_output
    self.send(msg)
  File "C:\TCL\Python\lib\http\client.py", line 964, in send
    self.connect()
  File "C:\TCL\Python\lib\site-packages\urllib3\connection.py", line 196, in connect
    conn = self._new_conn()
  File "C:\TCL\Python\lib\site-packages\urllib3\connection.py", line 180, in _new_conn
    self, "Failed to establish a new connection: %s" % e)
urllib3.exceptions.NewConnectionError: <urllib3.connection.HTTPConnection object at 0x000001AC445DB4A8>: Failed to establish a new connection: [WinError 10061] No connection could be made because the target machine actively refused it

During handling of the above exception, another exception occurred:

Traceback (most recent call last):
  File "C:\TCL\Python\lib\site-packages\requests\adapters.py", line 449, in send
    timeout=timeout
  File "C:\TCL\Python\lib\site-packages\urllib3\connectionpool.py", line 638, in urlopen
    _stacktrace=sys.exc_info()[2])
  File "C:\TCL\Python\lib\site-packages\urllib3\util\retry.py", line 398, in increment
    raise MaxRetryError(_pool, url, error or ResponseError(cause))
urllib3.exceptions.MaxRetryError: HTTPConnectionPool(host='localhost', port=5055): Max retries exceeded with url: /webhook (Caused by NewConnectionError('<urllib3.connection.HTTPConnection object at 0x000001AC445DB4A8>: Failed to establish a new connection: [WinError 10061] No connection could be made because the target machine actively refused it',))

During handling of the above exception, another exception occurred:

Traceback (most recent call last):
  File "C:\TCL\Python\lib\site-packages\rasa_core\actions\action.py", line 327, in run
    json=json, method="post", timeout=DEFAULT_REQUEST_TIMEOUT)
  File "C:\TCL\Python\lib\site-packages\rasa_core\utils.py", line 748, in request
    **kwargs)
  File "C:\TCL\Python\lib\site-packages\requests\api.py", line 60, in request
    return session.request(method=method, url=url, **kwargs)
  File "C:\TCL\Python\lib\site-packages\requests\sessions.py", line 524, in request
    resp = self.send(prep, **send_kwargs)
  File "C:\TCL\Python\lib\site-packages\requests\sessions.py", line 637, in send
    r = adapter.send(request, **kwargs)
  File "C:\TCL\Python\lib\site-packages\requests\adapters.py", line 516, in send
    raise ConnectionError(e, request=request)
requests.exceptions.ConnectionError: HTTPConnectionPool(host='localhost', port=5055): Max retries exceeded with url: /webhook (Caused by NewConnectionError('<urllib3.connection.HTTPConnection object at 0x000001AC445DB4A8>: Failed to establish a new connection: [WinError 10061] No connection could be made because the target machine actively refused it',))

During handling of the above exception, another exception occurred:

Traceback (most recent call last):
  File "C:\TCL\Python\lib\site-packages\rasa_core\processor.py", line 351, in _run_action
    events = action.run(dispatcher, tracker, self.domain)
  File "C:\TCL\Python\lib\site-packages\rasa_core\actions\action.py", line 348, in run
    raise Exception("Failed to execute custom action.")
Exception: Failed to execute custom action.
